<mujoco model="spherical_pendulum">
    <compiler angle="radian" coordinate="local"/>
    <option timestep="0.001" integrator="RK4" gravity="0 0 -9.81"/>
    <default>
        <geom rgba="1 1 1 1" />
        <joint damping="0.2"/>
    </default>
    <visual>
        <global offwidth="1920" offheight="1080"/>
    </visual>
    <asset>
        <texture name="checker" type="2d" builtin="checker" rgb1="0 0 0" rgb2="1 1 1" width="100" height="100" mark="none"/>
        <material name="checker_mat" texture="checker" specular="0.5" shininess="0.6" texrepeat="10 10"/>
    </asset>
    <worldbody>
        <light pos="0 0 10" dir="0 0 -1" diffuse="1 1 1" specular="0 0 0"/>
        <geom name="floor" type="plane" material="checker_mat" size="10 10 0.1"/>
        <body name="base" pos="0 0 0.15">
            <freejoint name="base_free"/>
            <geom name="base_sphere" type="sphere" size="0.15" mass="10" rgba="0.3 0.3 0.3 1"/>
            <body name="pendulum" pos="0 0 0">
                <joint name="ball_joint" type="ball" pos="0 0 0" range="0 3.1416" damping="0.2"/>
                <geom name="rod" type="capsule" fromto="0 0 0 0 0 1.0" size="0.01" mass="1.5" rgba="0 0.7 0.7 1"/>
                <geom name="tip_sphere" type="sphere" pos="0 0 1.0" size="0.05" mass="0.1" rgba="0.7 0.3 0.3 1"/>
                <site name="tip" pos="0 0 1.0" size="0.02"/>
            </body>
        </body>
    </worldbody>
    <actuator>
        <motor name="torque_x" joint="ball_joint" gear="1 0 0" ctrlrange="-50 50"/>
        <motor name="torque_y" joint="ball_joint" gear="0 1 0" ctrlrange="-50 50"/>
    </actuator>
    <sensor>
        <framequat name="angle" objtype="body" objname="pendulum"/>
        <frameangvel name="velocity" objtype="body" objname="pendulum"/>
        <framepos name="base_pos" objtype="body" objname="base"/>
        <framexaxis name="base_xaxis" objtype="body" objname="base"/>
        <frameyaxis name="base_yaxis" objtype="body" objname="base"/>
        <framezaxis name="base_zaxis" objtype="body" objname="base"/>
    </sensor>
</mujoco>