<mujoco model="robot_with_wheelbase">
    <compiler coordinate="local" angle="degree"/>
    <option timestep="0.001" integrator="RK4" gravity="0 0 -9.81" impratio="10"/>
    <default>
        <geom rgba="1 1 1 1" />
        <joint damping="0.2"/>
    </default>
    <visual>
        <global offwidth="1920" offheight="1080"/>
    </visual>
    <asset>
        <texture name="checker" type="2d" builtin="checker" rgb1="0 0 0" rgb2="1 1 1" width="100" height="100" mark="none"/>
        <material name="checker_mat" texture="checker" specular="0.5" shininess="0.6" texrepeat="10 10"/>
        <material name="robot_mat" rgba="0.5 0.5 0.5 1"/>
    </asset>
    <worldbody>
        <geom name="floor" type="plane" material="checker_mat" size="10 10 0.1"/>
        <body name="base" pos="0 0 0.15">
            <freejoint name="base_free"/>
            <geom name="base_sphere" type="sphere" size="0.15" mass="20" rgba="0.4 0.5 0.6 0.5" />
        </body>
        <body name="wheel_base" pos="0 0 0.35">
            <freejoint name="wheel_base_free"/>
            <!-- Robot Chassis -->
            <geom name="chassis_geom" type="cylinder" size="0.15 0.01" material="robot_mat" mass="1.0" rgba="1 0.5 0 0.5"/>
            <!-- Vertical pendulum -->
            <body name="pendulum" pos="0 0 0.3">
                <geom name="rod_geom" type="cylinder" size="0.01 0.3" rgba="1 0.2 0 0.5" mass="0.2"/>
                <!-- Ball Tip -->
                <body name="rod_tip" pos="0 0 0.3">
                    <geom name="rod_tip_geom" type="sphere" size="0.04" rgba="1 0.0 0 0.5" mass="0.05"/>
                </body>
            </body>
            <!-- Wheel 1: Positioned at 0 degrees, tilted -45 degrees toward ball center -->
            <body name="wheel1" pos="0.12727922061357855 0 -0.07" euler="0 -45 0">
                <joint name="wheel1_joint" type="hinge" axis="0 0 1" damping="0.1"/>
                <geom name="wheel1_geom" type="cylinder" size="0.03 0.02" rgba="0.5 0.5 0.5 1" mass="0.5" />
            </body>
            <body name="wheel2" pos="-0.06363961030678925 0.110227038425243 -0.07" euler="40.89339465 20.70481105 -112.2076543">
                <joint name="wheel2_joint" type="hinge" axis="0 0 1" damping="0.1"/>
                <geom name="wheel2_geom" type="cylinder" size="0.03 0.02" rgba="0.5 0.5 0.5 1" mass="0.5" />
            </body>
            <body name="wheel3" pos="-0.06363961030678925 -0.11022703842524297 -0.07" euler="-40.89339465 20.70481105 112.2076543">
                <joint name="wheel3_joint" type="hinge" axis="0 0 1" damping="0.1"/>
                <geom name="wheel3_geom" type="cylinder" size="0.03 0.02" rgba="0.5 0.5 0.5 1" mass="0.5" />
            </body>
        </body>
        <light name="diffuse_light" pos="0 0 5" dir="0 0 -1" directional="false" diffuse="0.8 0.8 0.8" specular="0 0 0" castshadow="false" />
    </worldbody>
    <sensor>
        <framequat name="pendulum_angle" objtype="body" objname="pendulum"/>
        <frameangvel name="pendulum_angular_velocity" objtype="body" objname="pendulum"/>
        <framelinvel name="base_linear_velocity" objtype="body" objname="base"/>
    </sensor>
    <actuator>
        <motor name="motor1" joint="wheel1_joint" ctrlrange="-5 5"/>
        <motor name="motor2" joint="wheel2_joint" ctrlrange="-5 5"/>
        <motor name="motor3" joint="wheel3_joint" ctrlrange="-5 5"/>
    </actuator>
    <contact>
        <!-- Anisotropic friction: zero along wheel z-axis, non-zero for theta -->
        <pair geom2="wheel1_geom" geom1="base_sphere" friction="0 1 0.005 0.0000 0.0000" condim="6" />
        <pair geom2="wheel2_geom" geom1="base_sphere" friction="0 1 0.005 0.0000 0.0000" condim="6" />
        <pair geom2="wheel3_geom" geom1="base_sphere" friction="0 1 0.005 0.0000 0.0000" condim="6" />
    </contact>
</mujoco>