<mujoco model="wheel_base">
  <!-- Robot Chassis -->
  <body name="robot" pos="0 0 0">
    <geom name="chassis_geom" type="cylinder" size="0.15 0.01" material="robot_mat" mass="1.0" rgba="1 0.5 0 1"/>
    <!-- Vertical Rod -->
    <body name="rod" pos="0 0 0.3">
      <geom name="rod_geom" type="cylinder" size="0.01 0.3" rgba="1 0.2 0 1" mass="0.2"/>
      <!-- Ball Tip -->
      <body name="rod_tip" pos="0 0 0.3"> <!-- Positioned at rod top (0.1 + 0.04 sphere radius) -->
        <geom name="rod_tip_geom" type="sphere" size="0.04" rgba="1 0.0 0 1" mass="0.05"/> <!-- Ball: radius 0.04m -->
      </body>
    </body>
    <!-- Wheel 1: Positioned at 0 degrees, tilted -45 degrees toward ball center -->
    <body name="wheel1" pos="0.12727922061357855 0 -0.07" euler="0 -45 0">
      <joint name="wheel1_joint" type="hinge" axis="0 0 1" damping="0.1"/>
      <geom name="wheel1_geom" type="cylinder" size="0.03 0.02" rgba="0.5 0.5 0.5 1" mass="0.2"/>
    </body>
    <body name="wheel2" pos="-0.06363961030678925 0.110227038425243 -0.07" euler="40.89339465 20.70481105 -112.2076543">
      <joint name="wheel2_joint" type="hinge" axis="0 0 1" damping="0.1"/>
      <geom name="wheel2_geom" type="cylinder" size="0.03 0.02" rgba="0.5 0.5 0.5 1" mass="0.2"/>
    </body>
    <body name="wheel3" pos="-0.06363961030678925 -0.11022703842524297 -0.07" euler="-40.89339465 20.70481105 112.2076543">
      <joint name="wheel3_joint" type="hinge" axis="0 0 1" damping="0.1"/>
      <geom name="wheel3_geom" type="cylinder" size="0.03 0.02" rgba="0.5 0.5 0.5 1" mass="0.2"/>
    </body>
  </body>
</mujoco>